Workbook

Sheet Tax rate
A2: Bậc thuế | B2: Phần thu nhập tính thuế/năm | C2: Phần thu nhập tính thuế/tháng | D2: Thuế suất (%)
B3: (triệu đồng) | C3: (triệu đồng)
A4: 1 | B4: Đến 60 | C4: Đến 5 | D4: 5
A5: 2 | B5: Trên 60 đến 120 | C5: Trên 5 đến 10 | D5: 10
A6: 3 | B6: Trên 120 đến 216 | C6: Trên 10 đến 18 | D6: 15
A7: 4 | B7: Trên 216 đến 384 | C7: Trên 18 đến 32 | D7: 20
A8: 5 | B8: Trên 384 đến 624 | C8: Trên 32 đến 52 | D8: 25
A9: 6 | B9: Trên 624 đến 960 | C9: Trên 52 đến 80 | D9: 30
A10: 7 | B10: Trên 960 | C10: Trên 80 | D10: 35

Sheet Payslip
A1: Renesas Design Vietnam Co., Ltd.
A3: Employee Pay Slip Checking
B5: Your registered family dependants: | D5: 1 | E5: person
B6: STI income if any: | F6: 0 | G6: VND | I6: 0
B7: SPECIAL BONUS, TOEIC, ONE-TIME income if any: | G7: VND | I7: 0
B8: TRAINING ALLOWANCE income if any: | G8: VND
D10: VND | E10: Days | F10: Amount
A11: Ø | B11: Current Basic Salary : | D11: 10000000 | E11: 22 | F11: =D11*E11/22 -> 10000000
B12: Previous Basic Salary | F12: =D12*E12/22 -> 0
B13: Master Allowance: | E13: =E11+E12 -> 22 | F13: =D13*E13/22 -> 0
B15: Your Gross income this month : | F15: =ROUND(SUM(F11:F13),-2)+SUM(F6:F8) -> 10000000
A17: Ø | B17: Add allowance : | D17: WAH | E17: Days | F17: Amount
B18: * Commuting allowance (w/o WFH): | E18: =E13-D18 -> 22 | F18: =ROUND(600000*ROUND(E18,0)/22,-2) -> 600000
B19: * Overtime allowance, in which: | D19: Rate | E19: Hours | F19: Amount
B20: - Working day | D20: 1.5 | F20: =($D$11/22/8)*D20*E20 -> 0
B21: - Working night | D21: 2.1 | F21: =($D$11/22/8)*D21*E21 -> 0
B22: - Day off / Holiday | D22: 2 | F22: =($D$11/22/8)*D22*E22 -> 0
B23: - Night off/ Holiday night | D23: 2.7 | F23: =($D$11/22/8)*D23*E23 -> 0
B24: - National day | D24: 3 | F24: =($D$11/22/8)*D24*E24 -> 0
B25: - National night | D25: 3.9 | F25: =($D$11/22/8)*D25*E25 -> 0
A27: Ø | B27: Adjustment before tax
E28: Days | F28: Amount
A29: Ø | B29: Deduction due to Late-in/Early-out/Absence | F29: =($D$11/22)*E29 -> 0
A31: Ø | B31: Less obligation on:
B32: * Social Insurance (8% salary) | F32: =IF(($D$11+D13)<(2340000*20),($D$11+D13)*8/100,(2340000*20*8%)) -> 800000
B33: * Health Insurance (1.5% salary) | F33: =IF(($D$11+D13)<(2340000*20),($D$11+D13)*1.5/100,(2340000*20*1.5%)) -> 150000
B34: * Unemployment Insurance (1% salary) | F34: =IF(($D$11+D13)<4960000*20,($D$11+D13)*1/100,4960000*20*1%) -> 100000
B35: * Personal Income Tax | F35: ='Tax Calculation'!X13 -> 0 | G35: (*) | H35: Temporary retained personal income tax (PIT) payable amount. This amount will be refund in Mar salary payment
B36: (See the calculation detail in "Tax Calculation" sheet) | F36: =SUM(F32:F35) -> 1050000
A38: Ø | B38: Net Income this month: | F38: =F15+F18+SUM(F20:F25)+F27-F29-F36 -> 9550000
A40: Ø | B40: Less STI payment on 19-Mar
A42: Ø | B42: Less Union Fee: | F42: 40000
A44: Ø | B44: Total Net Income this month: | F44: =ROUND(F38-F40-F42,-2) -> 9510000 | H44: =F44-F6 -> 9510000
B48: Prepared by: NT Lieu
B49: Version: 4.3
B50: 01/07/2017 (update Minimum basic salary from 1,210,000 dong --> 1,300,000 dong)
B51: 15/09/2017 (Modify Gross income formula)
B52: 01/01/2018 (Modify Unemployment insurance formula from 3,100,000 --> 3,980,000) (Modify Obligation Insurance includes Master Allowance if any)
B53: 01/07/2018 (update Minimum basic salary from 1,300,000 dong --> 1,390,000 dong)
B54: 01/01/2019 (update Unemployment insurance formula from 3,980,000 --> 4,180,000)
...

Sheet Tax Calculation
A2: BẢNG CHI TIẾT SỐ THUẾ THU NHẬP CỦA CÁ NHÂN NGƯỜI LAO ĐỘNG
A3: THÁNG - NĂM 2009
C6: [01] Mã số thuế cơ quan chi trả thu nhập:
C7: [02] Tên cơ quan chi trả thu nhập:
A9: STT | B9: ID Code | C9: Họ và tên cá nhân | D9: Mã số thuế cá nhân | E9: Tổng thu nhập | M9: Trừ thu nhập được miễn thuế & các khỏan phải nộp, được giảm trừ khác | W9: Thu nhập tính thuế | X9: Thuế TNCN phải nộp | Y9: Ghi chú
E10: Tổng số | F10: Trong đó | M10: Tổng số | N10: Số người đăng ký phụ thuộc Giảm trừ gia cảnh | O10: Tiền tăng ca, thêm giờ phải đóng thuế | P10: Tiền đóng BHXH, BHYT, BHTN theo quy định | Q10: Tiền chênh lệch tăng ca, thêm giờ | R10: Tiền chênh lệch tăng ca, thêm giờ (May Adjustment) | S10: Tiền bồi thường tai nạn lao động | T10: Tiền lương, trợ cấp do BHXH chi trả | U10: Giảm trừ gia cảnh | V10: Trừ các khỏan đóng góp vào quỹ từ thiện, khuyến học
F11: Lương | H11: Bonus & Others income | I11: Tiền trợ cấp đi lại | J11: OT | K11: Trừ tiền đi trễ về sớm | L11: Khác
A12: (1) | C12: (2) | D12: (3) | E12: (4)=(5)+…+(9) | F12: (5) | G12: (6) | H12: (7) | I12: (8) | L12: (9) | M12: (10)=(11)+…+(16) | P12: (11) | Q12: (12) | S12: (13) | T12: (14) | U12: (15) | V12: (16) | W12: (17)=(4)-(10) | X12: (18)
A13: 1 | E13: =+SUM(F13:L13) -> 10600000 | F13: =SUM(Payslip!F11:F13) -> 10000000 | H13: =SUM(Payslip!F6:F8) -> 0 | I13: =Payslip!F18 -> 600000 | J13: =SUM(Payslip!F20:F25) -> 0 | K13: =-Payslip!F29 -> 0 | L13: =Payslip!F27 -> 0 | M13: =SUM(P13:V13) -> 16450000 | N13: =Payslip!D5 -> 1 | O13: =(Payslip!$D$11/22/8)*SUM(Payslip!E20:E25) -> 0 | P13: =SUM(Payslip!F32:F34) -> 1050000 | Q13: =J13-O13 -> 0 | U13: =11000000+N13*4400000 -> 15400000 | W13: =+E13-M13 -> -5850000 | X13: =ROUND(IF(W13>80000000,((W13-80000000)*0.35+18150000),IF(AND(W13>52000000,W13<=80000000),((W13-52000000)*0.3+9750000),IF(AND(W13>32000000,W13<=52000000),((W13-32000000)*0.25+4750000),IF(AND(W13>18000000,W13<=32000000),((W13-18000000)*0.2+1950000),IF(AND(W13>10000000,W13<=18000000),((W13-10000000)*0.15+750000),IF(AND(W13>5000000,W13<=10000000),((W13-5000000)*0.1+250000),IF(W13<0,0,(W13*0.05)))))))),0) -> 0
